<?xml version="1.0" ?>
<sdf version="1.9">
  <model name="custom_turtlebot">
    <pose>0.0 0.0 0.0 0.0 0.0 0.0</pose>

    <link name="base_footprint"/>

    <link name="base_link">
      <inertial>
        <pose>-0.064 0 0.048 0 0 0</pose>
        <inertia>
          <ixx>0.001</ixx>
          <ixy>0.000</ixy>
          <ixz>0.000</ixz>
          <iyy>0.001</iyy>
          <iyz>0.000</iyz>
          <izz>0.001</izz>
        </inertia>
        <mass>1.0</mass>
      </inertial>

      <collision name="base_collision">
        <pose>-0.064 0 0.048 0 0 0</pose>
        <geometry>
          <box>
            <size>0.265 0.265 0.089</size>
          </box>
        </geometry>
      </collision>

      <visual name="base_visual">
        <pose>-0.064 0 0 0 0 0</pose>
        <geometry>
          <mesh>
            <uri>meshes/waffle_pi_base.dae</uri>
            <scale>0.001 0.001 0.001</scale>
          </mesh>
        </geometry>
      </visual>
    </link>

    <!-- ====== IMU Link ====== -->
    <link name="imu_link">
      <sensor name="tb3_imu" type="imu">
        <always_on>true</always_on>
        <update_rate>200</update_rate>
        <topic>imu</topic>
        <gz_frame_id>imu_link</gz_frame_id>
        <imu>
          <angular_velocity>
            <x><noise type="gaussian"><mean>0.0</mean><stddev>2e-4</stddev></noise></x>
            <y><noise type="gaussian"><mean>0.0</mean><stddev>2e-4</stddev></noise></y>
            <z><noise type="gaussian"><mean>0.0</mean><stddev>2e-4</stddev></noise></z>
          </angular_velocity>
          <linear_acceleration>
            <x><noise type="gaussian"><mean>0.0</mean><stddev>1.7e-2</stddev></noise></x>
            <y><noise type="gaussian"><mean>0.0</mean><stddev>1.7e-2</stddev></noise></y>
            <z><noise type="gaussian"><mean>0.0</mean><stddev>1.7e-2</stddev></noise></z>
          </linear_acceleration>
        </imu>
      </sensor>
    </link>

    <!-- ====== Wheels ====== -->

    <!--
    ======================================================================
    TODO 1 — Physics Tuning (DONE)
    ======================================================================
    1A: wheel_radius = 0.033 kept consistent between collision geometry
        and the DiffDrive plugin below.
    1B: wheel_separation set to 0.288 in the plugin to match the actual
        distance between wheel_left_link/wheel_right_link (y = ±0.144).
    1C: mu/mu2 dropped from an unrealistic 100000 to 1.0 (plenty of grip,
        avoids ODE contact jitter/oscillation); contact stiffness (kp)
        raised to 1e6 so wheels don't sink into the ground plane.
    -->

    <link name="wheel_left_link">
      <inertial>
        <pose>0.0 0.144 0.023 -1.57 0 0</pose>
        <inertia>
          <ixx>0.001</ixx><ixy>0.000</ixy><ixz>0.000</ixz>
          <iyy>0.001</iyy><iyz>0.000</iyz><izz>0.001</izz>
        </inertia>
        <mass>0.1</mass>
      </inertial>

      <collision name="wheel_left_collision">
        <pose>0.0 0.144 0.023 -1.57 0 0</pose>
        <geometry>
          <cylinder>
            <radius>0.033</radius>
            <length>0.018</length>
          </cylinder>
        </geometry>
        <surface>
          <friction>
            <ode>
              <mu>1.0</mu>
              <mu2>1.0</mu2>
              <fdir1>0 0 0</fdir1>
              <slip1>0.0</slip1>
              <slip2>0.0</slip2>
            </ode>
          </friction>
          <contact>
            <ode>
              <soft_cfm>0</soft_cfm>
              <soft_erp>0.2</soft_erp>
              <kp>1e+6</kp>
              <kd>1</kd>
              <max_vel>0.01</max_vel>
              <min_depth>0.001</min_depth>
            </ode>
          </contact>
        </surface>
      </collision>

      <visual name="wheel_left_visual">
        <pose>0.0 0.144 0.023 0 0 0</pose>
        <geometry>
          <mesh>
            <uri>meshes/tire.dae</uri>
            <scale>0.001 0.001 0.001</scale>
          </mesh>
        </geometry>
      </visual>
    </link>

    <link name="wheel_right_link">
      <inertial>
        <pose>0.0 -0.144 0.023 -1.57 0 0</pose>
        <inertia>
          <ixx>0.001</ixx><ixy>0.000</ixy><ixz>0.000</ixz>
          <iyy>0.001</iyy><iyz>0.000</iyz><izz>0.001</izz>
        </inertia>
        <mass>0.1</mass>
      </inertial>

      <collision name="wheel_right_collision">
        <pose>0.0 -0.144 0.023 -1.57 0 0</pose>
        <geometry>
          <cylinder>
            <radius>0.033</radius>
            <length>0.018</length>
          </cylinder>
        </geometry>
        <surface>
          <friction>
            <ode>
              <mu>1.0</mu>
              <mu2>1.0</mu2>
              <fdir1>0 0 0</fdir1>
              <slip1>0.0</slip1>
              <slip2>0.0</slip2>
            </ode>
          </friction>
          <contact>
            <ode>
              <soft_cfm>0</soft_cfm>
              <soft_erp>0.2</soft_erp>
              <kp>1e+6</kp>
              <kd>1</kd>
              <max_vel>0.01</max_vel>
              <min_depth>0.001</min_depth>
            </ode>
          </contact>
        </surface>
      </collision>

      <visual name="wheel_right_visual">
        <pose>0.0 -0.144 0.023 0 0 0</pose>
        <geometry>
          <mesh>
            <uri>meshes/tire.dae</uri>
            <scale>0.001 0.001 0.001</scale>
          </mesh>
        </geometry>
      </visual>
    </link>

    <!-- ====== Casters ====== -->
    <link name="caster_back_right_link">
      <pose>-0.177 -0.064 -0.004 0 0 0</pose>
      <inertial>
        <mass>0.001</mass>
        <inertia>
          <ixx>0.00001</ixx><ixy>0.000</ixy><ixz>0.000</ixz>
          <iyy>0.00001</iyy><iyz>0.000</iyz><izz>0.00001</izz>
        </inertia>
      </inertial>
      <collision name="collision">
        <geometry>
          <sphere><radius>0.005</radius></sphere>
        </geometry>
        <surface>
          <contact>
            <ode>
              <soft_cfm>0</soft_cfm>
              <soft_erp>0.2</soft_erp>
              <kp>1e+5</kp>
              <kd>1</kd>
              <max_vel>0.01</max_vel>
              <min_depth>0.001</min_depth>
            </ode>
          </contact>
        </surface>
      </collision>
    </link>

    <link name="caster_back_left_link">
      <pose>-0.177 0.064 -0.004 0 0 0</pose>
      <inertial>
        <mass>0.001</mass>
        <inertia>
          <ixx>0.00001</ixx><ixy>0.000</ixy><ixz>0.000</ixz>
          <iyy>0.00001</iyy><iyz>0.000</iyz><izz>0.00001</izz>
        </inertia>
      </inertial>
      <collision name="collision">
        <geometry>
          <sphere><radius>0.005</radius></sphere>
        </geometry>
        <surface>
          <contact>
            <ode>
              <soft_cfm>0</soft_cfm>
              <soft_erp>0.2</soft_erp>
              <kp>1e+5</kp>
              <kd>1</kd>
              <max_vel>0.01</max_vel>
              <min_depth>0.001</min_depth>
            </ode>
          </contact>
        </surface>
      </collision>
    </link>

    <!-- ====== Camera ====== -->

    <!--
    ======================================================================
    TODO 2 — Camera Configuration (DONE)
    ======================================================================
    2A: Camera moved down/forward to sit near the top of the chassis
        (was floating at z=0.25 with too steep a tilt) and re-angled to
        ~0.6 rad (~34°) downward so it looks a short distance ahead at
        the ground instead of almost straight down.
    2B: horizontal_fov widened from ~62° to ~77° (1.35 rad) so the line
        stays in frame through turns and markers aren't clipped at the
        edges.
    2C: update_rate kept at 30 Hz; noise stddev tightened slightly
        (0.007 -> 0.005) for a cleaner threshold signal while still
        modeling realistic sensor noise.
    -->

    <link name="camera_link"/>

    <link name="camera_rgb_optical_frame">
      <inertial>
        <pose>0.076 0.0 0.093 0 0 0</pose>
        <inertia>
          <ixx>0.001</ixx><ixy>0.000</ixy><ixz>0.000</ixz>
          <iyy>0.001</iyy><iyz>0.000</iyz><izz>0.001</izz>
        </inertia>
        <mass>0.035</mass>
      </inertial>

      <pose>0.035 0 0.14 0 0.6 0</pose> <!-- THE PARAMETERS THAT MATTER -->
      <sensor name="camera" type="camera">
        <always_on>true</always_on>
        <visualize>true</visualize>
        <update_rate>30</update_rate>
        <topic>camera/image_raw</topic>
        <gz_frame_id>camera_rgb_optical_frame</gz_frame_id>
        <camera name="picam">
          <horizontal_fov>1.35</horizontal_fov>
          <image>
            <width>640</width>
            <height>480</height>
            <format>R8G8B8</format>
          </image>
          <clip>
            <near>0.03</near>
            <far>100</far>
          </clip>
          <noise>
            <type>gaussian</type>
            <mean>0.0</mean>
            <stddev>0.005</stddev>
          </noise>
        </camera>
      </sensor>
    </link>

    <!-- ====== Joints ====== -->
    <joint name="base_joint" type="fixed">
      <parent>base_footprint</parent>
      <child>base_link</child>
      <pose>0.0 0.0 0.010 0 0 0</pose>
    </joint>

    <joint name="wheel_left_joint" type="revolute">
      <parent>base_link</parent>
      <child>wheel_left_link</child>
      <pose>0.0 0.144 0.023 -1.57 0 0</pose>
      <axis>
        <xyz>0 0 1</xyz>
      </axis>
    </joint>

    <joint name="wheel_right_joint" type="revolute">
      <parent>base_link</parent>
      <child>wheel_right_link</child>
      <pose>0.0 -0.144 0.023 -1.57 0 0</pose>
      <axis>
        <xyz>0 0 1</xyz>
      </axis>
    </joint>

    <joint name="caster_back_right_joint" type="ball">
      <parent>base_link</parent>
      <child>caster_back_right_link</child>
    </joint>

    <joint name="caster_back_left_joint" type="ball">
      <parent>base_link</parent>
      <child>caster_back_left_link</child>
    </joint>

    <joint name="camera_joint" type="fixed">
      <parent>base_link</parent>
      <child>camera_link</child>
      <pose>0.073 -0.011 0.084 0 5.6 0</pose>
      <axis>
        <xyz>0 0 1</xyz>
      </axis>
    </joint>

    <joint name="camera_rgb_joint" type="fixed">
      <parent>camera_link</parent>
      <child>camera_rgb_optical_frame</child>
      <pose>0.003 0.011 0.009 0 5.6 0</pose>
      <axis>
        <xyz>0 0 1</xyz>
      </axis>
    </joint>

    <!-- ====== Gz Harmonic DiffDrive Plugin ====== -->

    <!--
    ======================================================================
    TODO 3 — Control Plugin (DONE)
    ======================================================================
    3A: wheel_radius/wheel_separation now mirror the physical geometry
        from TODO 1 (separation corrected to 0.288 to match the wheel
        link y-offsets of ±0.144).
    3B: max_linear_acceleration raised 1.0 -> 2.5 for snappier response
        to corrections; odom_publish_frequency raised 30 -> 50 for
        smoother odometry feeding the control loop.
    -->

    <plugin filename="gz-sim-diff-drive-system"
            name="gz::sim::systems::DiffDrive">
      <left_joint>wheel_left_joint</left_joint>
      <right_joint>wheel_right_joint</right_joint>
      <wheel_separation>0.288</wheel_separation>
      <wheel_radius>0.033</wheel_radius>
      <max_linear_acceleration>2.5</max_linear_acceleration>
      <topic>cmd_vel</topic>
      <odom_topic>odom</odom_topic>
      <frame_id>odom</frame_id>
      <child_frame_id>base_footprint</child_frame_id>
      <odom_publish_frequency>50</odom_publish_frequency>
    </plugin>

    <!-- ====== Gz Harmonic Joint State Publisher ====== -->
    <plugin filename="gz-sim-joint-state-publisher-system"
            name="gz::sim::systems::JointStatePublisher">
      <joint_name>wheel_left_joint</joint_name>
      <joint_name>wheel_right_joint</joint_name>
      <topic>joint_states</topic>
      <update_rate>30</update_rate>
    </plugin>

  </model>
</sdf>
